Workbook

Sheet Overview
A1: HOTEL PMS (SaaS) PROPOSAL
A3: Client | B3: =Inputs!$B$4 -> Coastal Stay Hotels Pty Ltd
A4: Project | B4: =Inputs!$B$5 -> Cloud Hotel PMS (SaaS) – 3 properties
A5: Proposal ID | B5: =Inputs!$B$6 -> PRP-PMS-2026-002
A6: Date | B6: =Inputs!$B$7 -> 46303
A7: Presale lead | B7: =Inputs!$B$9 -> Presale A
A8: Valid for (days) | B8: =Inputs!$B$8 -> 30
A10: SUMMARY
A11: Properties | B11: =COUNTA(Scope!B5:B7) -> 3
A12: Total rooms | B12: =Scope!D8 -> 220
A13: Subscription Year 1 (AUD ex GST) | B13: =Pricing!G13 -> 49200
A14: One-off services, net (AUD ex GST) | B14: =Pricing!G43 -> 117117
A15: Total Year 1 (AUD ex GST) | B15: =Pricing!G46 -> 173697
A16: Total Year 1 (AUD inc GST) | B16: =Pricing!G48 -> 191066.7
A17: 3-year total (AUD ex GST) | B17: =Pricing!G56 -> 292000.12
A18: Implementation duration (weeks) | B18: =Timeline!E10 -> 26
A20: WHY THIS SOLUTION
A21: • One cloud PMS across all three hotels, no on-site servers to maintain.
A22: • Two-way channel manager removes double bookings and manual rate updates.
A23: • Mobile housekeeping and automated night audit save daily staff time.
A24: • Group dashboard gives head office live numbers across every property.
A25: • Phased roll-out starting with a pilot hotel and avoiding the peak season.
A27: See sheets: Scope, Pricing, Timeline, Terms. Change inputs in the Inputs sheet and everything updates.

Sheet Inputs
A1: INPUTS (blue text / yellow fill = editable)
A3: Parameter | B3: Value
A4: Client | B4: Coastal Stay Hotels Pty Ltd
A5: Project | B5: Cloud Hotel PMS (SaaS) – 3 properties
A6: Proposal ID | B6: PRP-PMS-2026-002
A7: Proposal date | B7: 46303
A8: Valid for (days) | B8: 30
A9: Presale lead | B9: Presale A
A10: Day rate (AUD ex GST) | B10: 1300
A11: GST rate | B11: 0.1
A12: Implementation discount | B12: 0.1
A13: Premium support (% of annual subscription) | B13: 0.15
A14: Services contingency (% of B + C) | B14: 0.1
A15: Annual price increase cap (CPI assumption) | B15: 0.03
A16: Subscription term (months, per year) | B16: 12
A18: Day rate, subscription prices, discount and support % are presale assumptions for illustration. Confirm with Sales/Finance before sending.

Sheet Scope
A1: SCOPE
A3: 1. Properties
A4: # | B4: Property | C4: Location | D4: Rooms | E4: Go-live wave
A5: 1 | B5: Byron Bay | C5: NSW | D5: 48 | E5: Wave 1 (pilot)
A6: 2 | B6: Gold Coast | C6: QLD | D6: 112 | E6: Wave 2
A7: 3 | B7: Sydney CBD | C7: NSW | D7: 60 | E7: Wave 3
B8: Total rooms | D8: =SUM(D5:D7) -> 220
A10: 2. Subscription modules
A11: # | B11: Module | C11: Key capabilities
A12: 1 | B12: Core PMS | C12: Reservations, front desk, folios and billing, rate plans, night audit, GST handling
A13: 2 | B13: Housekeeping & Maintenance | C13: Mobile room status, task allocation, maintenance tickets, lost property
A14: 3 | B14: Channel Manager | C14: Two-way sync with Booking.com, Expedia and Airbnb: rates, availability, reservations
A15: 4 | B15: Direct Booking Engine | C15: Website booking widget, packages and promo codes, payments
A16: 5 | B16: Revenue & Reporting | C16: Occupancy, ADR, RevPAR, pickup, budget vs actual, scheduled reports
A17: 6 | B17: Guest CRM & Messaging | C17: Guest profiles, preferences, automated pre-arrival and post-stay emails/SMS
A18: 7 | B18: Group Dashboard (HQ) | C18: Consolidated view across all properties, user roles and permissions
A20: 3. Integrations in scope
A21: 1 | B21: Channel manager connections (Booking.com, Expedia, Airbnb)
A22: 2 | B22: Payments: Stripe (all properties), Tyro (Gold Coast restaurant)
A23: 3 | B23: Accounting: Xero
A24: 4 | B24: Restaurant POS (Gold Coast)
A25: 5 | B25: Door locks: Salto
A26: 6 | B26: Website booking engine embed

Sheet Pricing
A1: PRICING (AUD, excluding GST unless stated)
A2: Blue = assumption, green = linked from another sheet, black = formula.
B4: A. SaaS SUBSCRIPTION (Year 1)
A5: # | B5: Module | C5: Unit | D5: Qty | E5: Price / unit / month | F5: Months | G5: Annual amount
A6: 1 | B6: =Scope!B12 -> Core PMS | C6: room / month | D6: =Scope!$D$8 -> 220 | E6: 9 | F6: =Inputs!$B$16 -> 12 | G6: =D6*E6*F6 -> 23760
A7: 2 | B7: =Scope!B13 -> Housekeeping & Maintenance | C7: room / month | D7: =Scope!$D$8 -> 220 | E7: 2 | F7: =Inputs!$B$16 -> 12 | G7: =D7*E7*F7 -> 5280
A8: 3 | B8: =Scope!B14 -> Channel Manager | C8: room / month | D8: =Scope!$D$8 -> 220 | E8: 2.5 | F8: =Inputs!$B$16 -> 12 | G8: =D8*E8*F8 -> 6600
A9: 4 | B9: =Scope!B15 -> Direct Booking Engine | C9: room / month | D9: =Scope!$D$8 -> 220 | E9: 1.5 | F9: =Inputs!$B$16 -> 12 | G9: =D9*E9*F9 -> 3960
A10: 5 | B10: =Scope!B16 -> Revenue & Reporting | C10: room / month | D10: =Scope!$D$8 -> 220 | E10: 1.5 | F10: =Inputs!$B$16 -> 12 | G10: =D10*E10*F10 -> 3960
A11: 6 | B11: =Scope!B17 -> Guest CRM & Messaging | C11: room / month | D11: =Scope!$D$8 -> 220 | E11: 1 | F11: =Inputs!$B$16 -> 12 | G11: =D11*E11*F11 -> 2640
A12: 7 | B12: =Scope!B18 -> Group Dashboard (HQ) | C12: flat / month | D12: 1 | E12: 250 | F12: =Inputs!$B$16 -> 12 | G12: =D12*E12*F12 -> 3000
B13: Total A – Subscription | G13: =SUM(G6:G12) -> 49200
B15: B. IMPLEMENTATION SERVICES
A16: # | B16: Item | C16: Unit | D16: Days | E16: Day rate | G16: Amount
A17: 1 | B17: Project management | C17: day | D17: 15 | E17: =Inputs!$B$10 -> 1300 | G17: =D17*E17 -> 19500
A18: 2 | B18: Discovery & solution design workshops | C18: day | D18: 6 | E18: =Inputs!$B$10 -> 1300 | G18: =D18*E18 -> 7800
A19: 3 | B19: System configuration (rooms, rates, taxes, packages, users) | C19: day | D19: 12 | E19: =Inputs!$B$10 -> 1300 | G19: =D19*E19 -> 15600
A20: 4 | B20: Data migration (guest profiles, future reservations) | C20: day | D20: 10 | E20: =Inputs!$B$10 -> 1300 | G20: =D20*E20 -> 13000
A21: 5 | B21: Staff training (on site, per property) | C21: day | D21: 8 | E21: =Inputs!$B$10 -> 1300 | G21: =D21*E21 -> 10400
A22: 6 | B22: Go-live support (hypercare) | C22: day | D22: 8 | E22: =Inputs!$B$10 -> 1300 | G22: =D22*E22 -> 10400
B23: Total B – Implementation | D23: =SUM(D17:D22) -> 59 | G23: =SUM(G17:G22) -> 76700
B25: C. INTEGRATIONS
A26: # | B26: Item | C26: Unit | D26: Days | E26: Day rate | G26: Amount
A27: 1 | B27: Channel manager (Booking.com, Expedia, Airbnb) | C27: day | D27: 6 | E27: =Inputs!$B$10 -> 1300 | G27: =D27*E27 -> 7800
A28: 2 | B28: Payments (Stripe, Tyro) | C28: day | D28: 5 | E28: =Inputs!$B$10 -> 1300 | G28: =D28*E28 -> 6500
A29: 3 | B29: Accounting (Xero) | C29: day | D29: 5 | E29: =Inputs!$B$10 -> 1300 | G29: =D29*E29 -> 6500
A30: 4 | B30: Restaurant POS (Gold Coast) | C30: day | D30: 7 | E30: =Inputs!$B$10 -> 1300 | G30: =D30*E30 -> 9100
A31: 5 | B31: Door locks (Salto) | C31: day | D31: 6 | E31: =Inputs!$B$10 -> 1300 | G31: =D31*E31 -> 7800
A32: 6 | B32: Website booking engine embed | C32: day | D32: 3 | E32: =Inputs!$B$10 -> 1300 | G32: =D32*E32 -> 3900
B33: Total C – Integrations | D33: =SUM(D27:D32) -> 32 | G33: =SUM(G27:G32) -> 41600
B35: D. SUPPORT & CONTINGENCY
A36: # | B36: Item | C36: Unit | D36: Rate | E36: Base | G36: Amount
A37: 1 | B37: Premium support (24/7 urgent, Year 1) | C37: % of A | D37: =Inputs!$B$13 -> 0.15 | E37: =G13 -> 49200 | G37: =D37*E37 -> 7380
A38: 2 | B38: Services contingency | C38: % of B + C | D38: =Inputs!$B$14 -> 0.1 | E38: =G23+G33 -> 118300 | G38: =D38*E38 -> 11830
B40: YEAR 1 SUMMARY
B41: One-off services before discount (B + C + contingency) | G41: =G23+G33+G38 -> 130130
B42: Implementation discount | G42: =-G41*Inputs!$B$12 -> -13013
B43: One-off services, net | G43: =G41+G42 -> 117117
B44: Subscription, Year 1 (A) | G44: =G13 -> 49200
B45: Premium support, Year 1 | G45: =G37 -> 7380
...

Sheet Timeline
A1: IMPLEMENTATION TIMELINE (weeks)
A3: Phase | B3: Activities | C3: Start (week) | D3: Duration (weeks) | E3: End (week)
A4: Discovery & design | B4: Kick-off, workshops, rate and room setup design | C4: 1 | D4: 3 | E4: =C4+D4-1 -> 3
A5: Build & integrations | B5: Configuration, channel manager, payments, Xero, POS, door locks | C5: 4 | D5: 8 | E5: =C5+D5-1 -> 11
A6: Wave 1 – Byron Bay | B6: Data migration, UAT, training, go-live (pilot) | C6: 10 | D6: 5 | E6: =C6+D6-1 -> 14
A7: Wave 2 – Gold Coast | B7: Migration, UAT, training, go-live | C7: 15 | D7: 4 | E7: =C7+D7-1 -> 18
A8: Wave 3 – Sydney CBD | B8: Migration, UAT, training, go-live | C8: 19 | D8: 4 | E8: =C8+D8-1 -> 22
A9: Hypercare & handover | B9: Stabilisation, final training, transition to support | C9: 23 | D9: 4 | E9: =C9+D9-1 -> 26
A10: Total duration (weeks) | E10: =MAX(E4:E9) -> 26
A12: Assumes kick-off in early November 2026. Wave 1 go-live avoids the Christmas–January peak (falls in about February 2027).

Sheet Terms
A1: ASSUMPTIONS, EXCLUSIONS & TERMS
A3: Type | B3: Detail
A4: Assumption | B4: Room counts, module selection and day estimates are initial estimates and will be confirmed after discovery.
A5: Assumption | B5: Client provides a project lead, data exports from the legacy PMS and timely UAT feedback.
A6: Assumption | B6: Subscription is billed monthly; prices shown are per room per month and exclude GST.
A7: Assumption | B7: Customer and payment data is hosted in Australian cloud regions.
A8: Exclusion | B8: Hardware (tablets, key encoders, card terminals) and network upgrades at the properties.
A9: Exclusion | B9: Third-party fees: channel/OTA commissions, payment processing fees, Xero, POS and door lock vendor charges.
A10: Exclusion | B10: Changes in scope after design sign-off, charged at the day rate in the Inputs sheet.
A11: Terms | B11: Suggested payment: 30% on signing, 40% across go-live waves, 30% after hypercare. Subscription starts at first go-live.
A12: Terms | B12: Minimum subscription term and price-increase cap to be confirmed in the contract.
A13: Terms | B13: This quote is valid for the number of days stated in the Inputs sheet.
